Workbook

Sheet Tổng quan
A1: Lịch đăng bài nhóm Facebook · 28/10 – 03/11/2026 (nick David)
A2: Số liệu đếm bằng công thức từ trang 'Từng bài'; trạng thái chốt lúc 28/10 14:00.
A4: Theo ngày | B4: T4 28/10 | C4: T5 29/10 | D4: T6 30/10 | E4: T7 31/10 | F4: CN 01/11 | G4: T2 02/11 | H4: T3 03/11 | I4: Cả tuần
A5: Tổng số bài | B5: =COUNTIF('Từng bài'!$A$2:$A$85,B$4) | C5: =COUNTIF('Từng bài'!$A$2:$A$85,C$4) | D5: =COUNTIF('Từng bài'!$A$2:$A$85,D$4) | E5: =COUNTIF('Từng bài'!$A$2:$A$85,E$4) | F5: =COUNTIF('Từng bài'!$A$2:$A$85,F$4) | G5: =COUNTIF('Từng bài'!$A$2:$A$85,G$4) | H5: =COUNTIF('Từng bài'!$A$2:$A$85,H$4) | I5: =SUM(B5:H5)
A6: Dự án: Golden Hill | B6: =COUNTIFS('Từng bài'!$A$2:$A$85,B$4,'Từng bài'!$C$2:$C$85,"Golden Hill") | C6: =COUNTIFS('Từng bài'!$A$2:$A$85,C$4,'Từng bài'!$C$2:$C$85,"Golden Hill") | D6: =COUNTIFS('Từng bài'!$A$2:$A$85,D$4,'Từng bài'!$C$2:$C$85,"Golden Hill") | E6: =COUNTIFS('Từng bài'!$A$2:$A$85,E$4,'Từng bài'!$C$2:$C$85,"Golden Hill") | F6: =COUNTIFS('Từng bài'!$A$2:$A$85,F$4,'Từng bài'!$C$2:$C$85,"Golden Hill") | G6: =COUNTIFS('Từng bài'!$A$2:$A$85,G$4,'Từng bài'!$C$2:$C$85,"Golden Hill") | H6: =COUNTIFS('Từng bài'!$A$2:$A$85,H$4,'Từng bài'!$C$2:$C$85,"Golden Hill") | I6: =SUM(B6:H6)
A7: Dự án: Sun City (cho thuê) | B7: =COUNTIFS('Từng bài'!$A$2:$A$85,B$4,'Từng bài'!$C$2:$C$85,"Sun City (cho thuê)") | C7: =COUNTIFS('Từng bài'!$A$2:$A$85,C$4,'Từng bài'!$C$2:$C$85,"Sun City (cho thuê)") | D7: =COUNTIFS('Từng bài'!$A$2:$A$85,D$4,'Từng bài'!$C$2:$C$85,"Sun City (cho thuê)") | E7: =COUNTIFS('Từng bài'!$A$2:$A$85,E$4,'Từng bài'!$C$2:$C$85,"Sun City (cho thuê)") | F7: =COUNTIFS('Từng bài'!$A$2:$A$85,F$4,'Từng bài'!$C$2:$C$85,"Sun City (cho thuê)") | G7: =COUNTIFS('Từng bài'!$A$2:$A$85,G$4,'Từng bài'!$C$2:$C$85,"Sun City (cho thuê)") | H7: =COUNTIFS('Từng bài'!$A$2:$A$85,H$4,'Từng bài'!$C$2:$C$85,"Sun City (cho thuê)") | I7: =SUM(B7:H7)
A8: Nhóm: Nhà đất / BĐS | B8: =COUNTIFS('Từng bài'!$A$2:$A$85,B$4,'Từng bài'!$J$2:$J$85,"Nhà đất / BĐS") | C8: =COUNTIFS('Từng bài'!$A$2:$A$85,C$4,'Từng bài'!$J$2:$J$85,"Nhà đất / BĐS") | D8: =COUNTIFS('Từng bài'!$A$2:$A$85,D$4,'Từng bài'!$J$2:$J$85,"Nhà đất / BĐS") | E8: =COUNTIFS('Từng bài'!$A$2:$A$85,E$4,'Từng bài'!$J$2:$J$85,"Nhà đất / BĐS") | F8: =COUNTIFS('Từng bài'!$A$2:$A$85,F$4,'Từng bài'!$J$2:$J$85,"Nhà đất / BĐS") | G8: =COUNTIFS('Từng bài'!$A$2:$A$85,G$4,'Từng bài'!$J$2:$J$85,"Nhà đất / BĐS") | H8: =COUNTIFS('Từng bài'!$A$2:$A$85,H$4,'Từng bài'!$J$2:$J$85,"Nhà đất / BĐS") | I8: =SUM(B8:H8)
A9: Nhóm: Cộng đồng / hội | B9: =COUNTIFS('Từng bài'!$A$2:$A$85,B$4,'Từng bài'!$J$2:$J$85,"Cộng đồng / hội") | C9: =COUNTIFS('Từng bài'!$A$2:$A$85,C$4,'Từng bài'!$J$2:$J$85,"Cộng đồng / hội") | D9: =COUNTIFS('Từng bài'!$A$2:$A$85,D$4,'Từng bài'!$J$2:$J$85,"Cộng đồng / hội") | E9: =COUNTIFS('Từng bài'!$A$2:$A$85,E$4,'Từng bài'!$J$2:$J$85,"Cộng đồng / hội") | F9: =COUNTIFS('Từng bài'!$A$2:$A$85,F$4,'Từng bài'!$J$2:$J$85,"Cộng đồng / hội") | G9: =COUNTIFS('Từng bài'!$A$2:$A$85,G$4,'Từng bài'!$J$2:$J$85,"Cộng đồng / hội") | H9: =COUNTIFS('Từng bài'!$A$2:$A$85,H$4,'Từng bài'!$J$2:$J$85,"Cộng đồng / hội") | I9: =SUM(B9:H9)
A10: Nhóm: KCN / nhà trọ | B10: =COUNTIFS('Từng bài'!$A$2:$A$85,B$4,'Từng bài'!$J$2:$J$85,"KCN / nhà trọ") | C10: =COUNTIFS('Từng bài'!$A$2:$A$85,C$4,'Từng bài'!$J$2:$J$85,"KCN / nhà trọ") | D10: =COUNTIFS('Từng bài'!$A$2:$A$85,D$4,'Từng bài'!$J$2:$J$85,"KCN / nhà trọ") | E10: =COUNTIFS('Từng bài'!$A$2:$A$85,E$4,'Từng bài'!$J$2:$J$85,"KCN / nhà trọ") | F10: =COUNTIFS('Từng bài'!$A$2:$A$85,F$4,'Từng bài'!$J$2:$J$85,"KCN / nhà trọ") | G10: =COUNTIFS('Từng bài'!$A$2:$A$85,G$4,'Từng bài'!$J$2:$J$85,"KCN / nhà trọ") | H10: =COUNTIFS('Từng bài'!$A$2:$A$85,H$4,'Từng bài'!$J$2:$J$85,"KCN / nhà trọ") | I10: =SUM(B10:H10)
A11: Nhóm: Chợ địa phương | B11: =COUNTIFS('Từng bài'!$A$2:$A$85,B$4,'Từng bài'!$J$2:$J$85,"Chợ địa phương") | C11: =COUNTIFS('Từng bài'!$A$2:$A$85,C$4,'Từng bài'!$J$2:$J$85,"Chợ địa phương") | D11: =COUNTIFS('Từng bài'!$A$2:$A$85,D$4,'Từng bài'!$J$2:$J$85,"Chợ địa phương") | E11: =COUNTIFS('Từng bài'!$A$2:$A$85,E$4,'Từng bài'!$J$2:$J$85,"Chợ địa phương") | F11: =COUNTIFS('Từng bài'!$A$2:$A$85,F$4,'Từng bài'!$J$2:$J$85,"Chợ địa phương") | G11: =COUNTIFS('Từng bài'!$A$2:$A$85,G$4,'Từng bài'!$J$2:$J$85,"Chợ địa phương") | H11: =COUNTIFS('Từng bài'!$A$2:$A$85,H$4,'Từng bài'!$J$2:$J$85,"Chợ địa phương") | I11: =SUM(B11:H11)
A12: Dạng: 3 ảnh | B12: =COUNTIFS('Từng bài'!$A$2:$A$85,B$4,'Từng bài'!$L$2:$L$85,"3 ảnh") | C12: =COUNTIFS('Từng bài'!$A$2:$A$85,C$4,'Từng bài'!$L$2:$L$85,"3 ảnh") | D12: =COUNTIFS('Từng bài'!$A$2:$A$85,D$4,'Từng bài'!$L$2:$L$85,"3 ảnh") | E12: =COUNTIFS('Từng bài'!$A$2:$A$85,E$4,'Từng bài'!$L$2:$L$85,"3 ảnh") | F12: =COUNTIFS('Từng bài'!$A$2:$A$85,F$4,'Từng bài'!$L$2:$L$85,"3 ảnh") | G12: =COUNTIFS('Từng bài'!$A$2:$A$85,G$4,'Từng bài'!$L$2:$L$85,"3 ảnh") | H12: =COUNTIFS('Từng bài'!$A$2:$A$85,H$4,'Từng bài'!$L$2:$L$85,"3 ảnh") | I12: =SUM(B12:H12)
A13: Dạng: Video | B13: =COUNTIFS('Từng bài'!$A$2:$A$85,B$4,'Từng bài'!$L$2:$L$85,"Video") | C13: =COUNTIFS('Từng bài'!$A$2:$A$85,C$4,'Từng bài'!$L$2:$L$85,"Video") | D13: =COUNTIFS('Từng bài'!$A$2:$A$85,D$4,'Từng bài'!$L$2:$L$85,"Video") | E13: =COUNTIFS('Từng bài'!$A$2:$A$85,E$4,'Từng bài'!$L$2:$L$85,"Video") | F13: =COUNTIFS('Từng bài'!$A$2:$A$85,F$4,'Từng bài'!$L$2:$L$85,"Video") | G13: =COUNTIFS('Từng bài'!$A$2:$A$85,G$4,'Từng bài'!$L$2:$L$85,"Video") | H13: =COUNTIFS('Từng bài'!$A$2:$A$85,H$4,'Từng bài'!$L$2:$L$85,"Video") | I13: =SUM(B13:H13)
A14: Trạng thái: Đã hiện | B14: =COUNTIFS('Từng bài'!$A$2:$A$85,B$4,'Từng bài'!$N$2:$N$85,"Đã hiện") | C14: =COUNTIFS('Từng bài'!$A$2:$A$85,C$4,'Từng bài'!$N$2:$N$85,"Đã hiện") | D14: =COUNTIFS('Từng bài'!$A$2:$A$85,D$4,'Từng bài'!$N$2:$N$85,"Đã hiện") | E14: =COUNTIFS('Từng bài'!$A$2:$A$85,E$4,'Từng bài'!$N$2:$N$85,"Đã hiện") | F14: =COUNTIFS('Từng bài'!$A$2:$A$85,F$4,'Từng bài'!$N$2:$N$85,"Đã hiện") | G14: =COUNTIFS('Từng bài'!$A$2:$A$85,G$4,'Từng bài'!$N$2:$N$85,"Đã hiện") | H14: =COUNTIFS('Từng bài'!$A$2:$A$85,H$4,'Từng bài'!$N$2:$N$85,"Đã hiện") | I14: =SUM(B14:H14)
A15: Trạng thái: Chờ nhóm duyệt | B15: =COUNTIFS('Từng bài'!$A$2:$A$85,B$4,'Từng bài'!$N$2:$N$85,"Chờ nhóm duyệt") | C15: =COUNTIFS('Từng bài'!$A$2:$A$85,C$4,'Từng bài'!$N$2:$N$85,"Chờ nhóm duyệt") | D15: =COUNTIFS('Từng bài'!$A$2:$A$85,D$4,'Từng bài'!$N$2:$N$85,"Chờ nhóm duyệt") | E15: =COUNTIFS('Từng bài'!$A$2:$A$85,E$4,'Từng bài'!$N$2:$N$85,"Chờ nhóm duyệt") | F15: =COUNTIFS('Từng bài'!$A$2:$A$85,F$4,'Từng bài'!$N$2:$N$85,"Chờ nhóm duyệt") | G15: =COUNTIFS('Từng bài'!$A$2:$A$85,G$4,'Từng bài'!$N$2:$N$85,"Chờ nhóm duyệt") | H15: =COUNTIFS('Từng bài'!$A$2:$A$85,H$4,'Từng bài'!$N$2:$N$85,"Chờ nhóm duyệt") | I15: =SUM(B15:H15)
A16: Trạng thái: Hẹn đăng | B16: =COUNTIFS('Từng bài'!$A$2:$A$85,B$4,'Từng bài'!$N$2:$N$85,"Hẹn đăng") | C16: =COUNTIFS('Từng bài'!$A$2:$A$85,C$4,'Từng bài'!$N$2:$N$85,"Hẹn đăng") | D16: =COUNTIFS('Từng bài'!$A$2:$A$85,D$4,'Từng bài'!$N$2:$N$85,"Hẹn đăng") | E16: =COUNTIFS('Từng bài'!$A$2:$A$85,E$4,'Từng bài'!$N$2:$N$85,"Hẹn đăng") | F16: =COUNTIFS('Từng bài'!$A$2:$A$85,F$4,'Từng bài'!$N$2:$N$85,"Hẹn đăng") | G16: =COUNTIFS('Từng bài'!$A$2:$A$85,G$4,'Từng bài'!$N$2:$N$85,"Hẹn đăng") | H16: =COUNTIFS('Từng bài'!$A$2:$A$85,H$4,'Từng bài'!$N$2:$N$85,"Hẹn đăng") | I16: =SUM(B16:H16)
A17: Trạng thái: Hỏng | B17: =COUNTIFS('Từng bài'!$A$2:$A$85,B$4,'Từng bài'!$N$2:$N$85,"Hỏng") | C17: =COUNTIFS('Từng bài'!$A$2:$A$85,C$4,'Từng bài'!$N$2:$N$85,"Hỏng") | D17: =COUNTIFS('Từng bài'!$A$2:$A$85,D$4,'Từng bài'!$N$2:$N$85,"Hỏng") | E17: =COUNTIFS('Từng bài'!$A$2:$A$85,E$4,'Từng bài'!$N$2:$N$85,"Hỏng") | F17: =COUNTIFS('Từng bài'!$A$2:$A$85,F$4,'Từng bài'!$N$2:$N$85,"Hỏng") | G17: =COUNTIFS('Từng bài'!$A$2:$A$85,G$4,'Từng bài'!$N$2:$N$85,"Hỏng") | H17: =COUNTIFS('Từng bài'!$A$2:$A$85,H$4,'Từng bài'!$N$2:$N$85,"Hỏng") | I17: =SUM(B17:H17)
A18: Có ảnh chính sách ghi 'đến 31/10' | B18: =COUNTIFS('Từng bài'!$A$2:$A$85,B$4,'Từng bài'!$M$2:$M$85,"Có") | C18: =COUNTIFS('Từng bài'!$A$2:$A$85,C$4,'Từng bài'!$M$2:$M$85,"Có") | D18: =COUNTIFS('Từng bài'!$A$2:$A$85,D$4,'Từng bài'!$M$2:$M$85,"Có") | E18: =COUNTIFS('Từng bài'!$A$2:$A$85,E$4,'Từng bài'!$M$2:$M$85,"Có") | F18: =COUNTIFS('Từng bài'!$A$2:$A$85,F$4,'Từng bài'!$M$2:$M$85,"Có") | G18: =COUNTIFS('Từng bài'!$A$2:$A$85,G$4,'Từng bài'!$M$2:$M$85,"Có") | H18: =COUNTIFS('Từng bài'!$A$2:$A$85,H$4,'Từng bài'!$M$2:$M$85,"Có") | I18: =SUM(B18:H18)
A20: Việc cần xử lý
A21: 1. Sun City chỉ có 2 bài (29/10). Đề xuất thêm 1 bài/ngày từ 30/10 vào nhóm nhà đất Bắc Giang.
A22: 2. 82 bài Golden Hill dùng 3 ảnh, chưa dùng video định vị. Đề xuất đổi khoảng một nửa sang video để so sánh.
A23: 3. Bài từ 01/11 vẫn kèm ảnh chính sách ghi ưu đãi 'đến 31/10': cần ảnh chính sách tháng 11 hoặc bỏ ảnh này.
A24: 4. Luật lịch: tối đa 12 bài/ngày, mỗi bài cách nhau ≥ 25 phút, mỗi nhóm cách ≥ 3 ngày (config/settings.json).

Sheet Từng bài
A1: Ngày | B1: Giờ | C1: Dự án | D1: Góc | E1: Loại bài (góc) | F1: Tiêu đề bài | G1: Đối tượng | H1: Mã khách báo | I1: Nhóm | J1: Loại nhóm | K1: Thành viên | L1: Ảnh/video | M1: Có ảnh chính sách | N1: Trạng thái | O1: Mã bài | P1: Mã nhóm
A2: T4 28/10 | B2: 07:20 | C2: Golden Hill | D2: 1 | E2: Rủ anh em, họ hàng mua gần nhau | F2: 🏡 RỦ ANH EM XEM ĐẤT? CHỈ VỚI 500 TRIỆU ĐÃ SỞ HỮU LÔ ĐẤT | G2: xay-nha-gia-dinh | H2: TY71 | I2: Nhà Đất Lạng Sơn | J2: Nhà đất / BĐS | K2: 86000 | L2: 3 ảnh | M2: Có | N2: Đã hiện | O2: 372 | P2: 310
A3: T4 28/10 | B3: 08:26 | C3: Golden Hill | D3: 2 | E3: Hai vợ chồng cùng đi xem | F3: 🏡 VỢ CHỒNG LÀM NHÀ? CHỈ VỚI 500 TRIỆU ĐÃ SỞ HỮU LÔ ĐẤT | G3: gia-dinh-tre-xay-nha | H3: BH30 | I3: Chợ Chùa Hang Linh Sơn Đồng Hỷ Thái Nguyên | J3: Chợ địa phương | K3: 59000 | L3: 3 ảnh | M3: Có | N3: Chờ nhóm duyệt | O3: 373 | P3: 311
A4: T4 28/10 | B4: 10:02 | C4: Golden Hill | D4: 3 | E4: Đất làm nhà cưới cho con | F4: 🏡 ĐẤT CHO CON? CHỈ VỚI 500 TRIỆU ĐÃ SỞ HỮU LÔ ĐẤT | G4: Cha mẹ mua cho con | H4: YT97 | I4: Nhã Nam reading club | J4: Cộng đồng / hội | K4: 259000 | L4: 3 ảnh | M4: Có | N4: Chờ nhóm duyệt | O4: 374 | P4: 139
A5: T4 28/10 | B5: 10:35 | C5: Golden Hill | D5: 6 | E5: Dạo một vòng bằng flycam | F5: 📍 XEM TỪ TRÊN CAO? CHỈ VỚI 500 TRIỆU ĐÃ SỞ HỮU LÔ ĐẤT | G5: nguoi-tim-dat-o | H5: TY72 | I5: Mua Bán Bất Động Sản Bắc Giang | J5: Nhà đất / BĐS | K5: 36000 | L5: 3 ảnh | M5: Có | N5: Đã hiện | O5: 375 | P5: 35
A6: T4 28/10 | B6: 13:58 | C6: Golden Hill | D6: 8 | E6: Làm KCN, về quê có đất | F6: 🏡 ĐI CA KCN? CHỈ VỚI 500 TRIỆU ĐÃ SỞ HỮU LÔ ĐẤT | G6: cong-nhan-kcn-lam-nha | H6: TY73 | I6: KCN Song Khê - Nội Hoàng - Bắc Giang | J6: KCN / nhà trọ | K6: 70000 | L6: 3 ảnh | M6: Có | N6: Hẹn đăng | O6: 377 | P6: 542
A7: T4 28/10 | B7: 14:46 | C7: Golden Hill | D7: 9 | E7: Khu dân cư mới giữa trung tâm xã | F7: 📍 KHU DÂN CƯ MỚI? CHỈ VỚI 500 TRIỆU ĐÃ SỞ HỮU LÔ ĐẤT | G7: nguoi-yen-the | H7: YT99 | I7: Hội Người Yên Thế | J7: Cộng đồng / hội | K7: 7400 | L7: 3 ảnh | M7: Có | N7: Hẹn đăng | O7: 378 | P7: 19
A8: T4 28/10 | B8: 15:52 | C8: Golden Hill | D8: 10 | E8: Nhìn từ trên cao / mặt đường | F8: 📍 CHỌN ĐẤT XÂY NHÀ? CHỈ VỚI 500 TRIỆU ĐÃ SỞ HỮU LÔ ĐẤT | G8: nguoi-xay-nha-mat-duong | H8: TY74 | I8: Chợ Nhà Đất Lạng Sơn - Nơi mua bán, thuê và cho thuê bất động sản Lạng Sơn | J8: Nhà đất / BĐS | K8: 170000 | L8: 3 ảnh | M8: Có | N8: Hẹn đăng | O8: 379 | P8: 308
A9: T4 28/10 | B9: 17:10 | C9: Golden Hill | D9: 11 | E9: Vẫn có khách giao dịch, CĐT dẫn đi xem | F9: 🔥 HẸN NGÀY XEM ĐẤT? CHỈ VỚI 500 TRIỆU ĐÃ SỞ HỮU LÔ ĐẤT | G9: Người tìm đất xây nhà | H9: YT100 | I9: BẤT ĐỘNG SẢN YÊN THẾ | J9: Nhà đất / BĐS | K9: 6200 | L9: 3 ảnh | M9: Có | N9: Hẹn đăng | O9: 380 | P9: 7
A10: T4 28/10 | B10: 18:39 | C10: Golden Hill | D10: 12 | E10: Người các xã lân cận | F10: 🏡 Ở QUANH YÊN THẾ? CHỈ VỚI 500 TRIỆU ĐÃ SỞ HỮU LÔ ĐẤT | G10: nguoi-yen-the-xa-que | H10: BH31 | I10: Nhà Đất xã Yên Thế, Đồng Kỳ, Xuân Lương, Tam Tiến, Bố Hạ tỉnh Bắc Ninh | J10: Nhà đất / BĐS | K10: 1200 | L10: 3 ảnh | M10: Có | N10: Hẹn đăng | O10: 381 | P10: 49
A11: T4 28/10 | B11: 19:35 | C11: Golden Hill | D11: 7 | E11: Hỏi nhanh – đáp nhanh | F11: ✅ HỎI TRƯỚC KHI MUA? CHỈ VỚI 500 TRIỆU ĐÃ SỞ HỮU LÔ ĐẤT | G11: mua-o-lan-dau | H11: YT98 | I11: Nhà đất Lạng Sơn - Mua bán, Cho thuê BĐS | J11: Nhà đất / BĐS | K11: 56000 | L11: 3 ảnh | M11: Có | N11: Hẹn đăng | O11: 376 | P11: 312
A12: T4 28/10 | B12: 20:32 | C12: Golden Hill | D12: 5 | E12: Tối cho con ra quảng trường chơi | F12: 🌙 QUẢNG TRƯỜNG SÁNG ĐÈN: CHỈ VỚI 500 TRIỆU ĐÃ SỞ HỮU LÔ ĐẤT | G12: Cha mẹ mua cho con | H12: YT101 | I12: Xã Đồng Kỳ - Bắc Ninh ( Mới ): Thông Tin - Trao Đổi, Mua Bán | J12: Cộng đồng / hội | K12: 0 | L12: 3 ảnh | M12: Có | N12: Hẹn đăng | O12: 382 | P12: 20
A13: T4 28/10 | B13: 21:47 | C13: Golden Hill | D13: 5 | E13: Tối cho con ra quảng trường chơi | F13: 🔥 CON CÓ SÂN CHƠI? CHỈ VỚI 500 TRIỆU ĐÃ SỞ HỮU LÔ ĐẤT | G13: Gia đình trẻ | H13: TY75 | I13: Yên Thế Online | J13: Cộng đồng / hội | K13: 13000 | L13: 3 ảnh | M13: Có | N13: Hẹn đăng | O13: 383 | P13: 46
... A85: T3 03/11 | B85: 21:46 | C85: Golden Hill | D85: 5 | E85: Tối cho con ra quảng trường chơi | F85: 🌙 HỘI DIỀU LÀM NHÀ? CHỈ VỚI 500 TRIỆU ĐÃ SỞ HỮU LÔ ĐẤT | G85: hoi-so-thich-lam-nha | H85: TY98 | I85: Hội Diều Sáo Tân Yên | J85: Cộng đồng / hội | K85: 52000 | L85: 3 ảnh | M85: Có | N85: Hẹn đăng | O85: 461 | P85: 128

Sheet Theo nhóm
A1: Mã nhóm | B1: Nhóm | C1: Loại nhóm | D1: Thành viên | E1: Số bài tuần này | F1: Các lần đăng tuần này (ngày giờ · góc) | G1: Trước 28/10: đã đăng | H1: Trước 28/10: hiện ngay | I1: Tỉ lệ hiện ngay | J1: Bài cuối trước đây | K1: Nhận xét
A2: 542 | B2: KCN Song Khê - Nội Hoàng - Bắc Giang | C2: KCN / nhà trọ | D2: 70000 | E2: =COUNTIF('Từng bài'!$P$2:$P$85,A2) | F2: T4 28/10 13:58 · góc 8; T7 31/10 16:26 · góc 7; T3 03/11 18:03 · góc 1 | G2: 0 | H2: 0 | I2: =IF(G2=0,"-",H2/G2) | K2: Nhóm mới, chưa đăng lần nào: theo dõi bài đầu
A3: 139 | B3: Nhã Nam reading club | C3: Cộng đồng / hội | D3: 259000 | E3: =COUNTIF('Từng bài'!$P$2:$P$85,A3) | F3: T4 28/10 10:02 · góc 3; T7 31/10 12:33 · góc 2; T3 03/11 16:21 · góc 4 | G3: 0 | H3: 0 | I3: =IF(G3=0,"-",H3/G3) | K3: Nhóm mới, chưa đăng lần nào: theo dõi bài đầu
A4: 111 | B4: BDS Tân yên Bắc Ninh | C4: Nhà đất / BĐS | D4: 50000 | E4: =COUNTIF('Từng bài'!$P$2:$P$85,A4) | F4: T6 30/10 14:31 · góc 8; T2 02/11 20:40 · góc 5 | G4: 1 | H4: 1 | I4: =IF(G4=0,"-",H4/G4) | J4: 2026-10-27 | K4: Tốt: phần lớn bài hiện ngay
A5: 7 | B5: BẤT ĐỘNG SẢN YÊN THẾ | C5: Nhà đất / BĐS | D5: 6200 | E5: =COUNTIF('Từng bài'!$P$2:$P$85,A5) | F5: T4 28/10 17:10 · góc 11; T7 31/10 20:41 · góc 5 | G5: 4 | H5: 4 | I5: =IF(G5=0,"-",H5/G5) | J5: 2026-10-22 | K5: Tốt: phần lớn bài hiện ngay
A6: 18 | B6: Bất Động Sản Tân Yên - Bắc Giang | C6: Nhà đất / BĐS | D6: 14000 | E6: =COUNTIF('Từng bài'!$P$2:$P$85,A6) | F6: T5 29/10 20:32 · góc 5; T2 02/11 15:18 · góc 1 | G6: 5 | H6: 4 | I6: =IF(G6=0,"-",H6/G6) | J6: 2026-10-25 | K6: Tốt: phần lớn bài hiện ngay
A7: 81 | B7: CHỢ QUÊ :CẦU GỒ - MỎ TRẠNG - XUÂN LƯƠNG - CANH NẬU | C7: Chợ địa phương | D7: 9700 | E7: =COUNTIF('Từng bài'!$P$2:$P$85,A7) | F7: T6 30/10 20:02 · góc 5; T3 03/11 13:51 · góc 11 | G7: 4 | H7: 4 | I7: =IF(G7=0,"-",H7/G7) | J7: 2026-10-26 | K7: Tốt: phần lớn bài hiện ngay
A8: 549 | B8: Chợ My Điền 01,2,3 KCN Đình Trám , Vân Trung , Quang Châu , Bắc Ninh | C8: KCN / nhà trọ | D8: 55000 | E8: =COUNTIF('Từng bài'!$P$2:$P$85,A8) | F8: T6 30/10 19:21 · góc 5; T3 03/11 20:22 · góc 5 | G8: 0 | H8: 0 | I8: =IF(G8=0,"-",H8/G8) | K8: Nhóm mới, chưa đăng lần nào: theo dõi bài đầu
A9: 137 | B9: Chợ Mọc Tân Yên Bắc Giang | C9: Chợ địa phương | D9: 78000 | E9: =COUNTIF('Từng bài'!$P$2:$P$85,A9) | F9: T5 29/10 14:46 · góc 9; T2 02/11 08:41 · góc 9 | G9: 4 | H9: 4 | I9: =IF(G9=0,"-",H9/G9) | J9: 2026-10-24 | K9: Tốt: phần lớn bài hiện ngay
A10: 115 | B10: Chợ Tân Yên - Bắc Giang | C10: Chợ địa phương | D10: 50000 | E10: =COUNTIF('Từng bài'!$P$2:$P$85,A10) | F10: T6 30/10 09:57 · góc 2; T3 03/11 09:47 · góc 8 | G10: 4 | H10: 4 | I10: =IF(G10=0,"-",H10/G10) | J10: 2026-10-26 | K10: Tốt: phần lớn bài hiện ngay
A11: 546 | B11: Chợ Vân Cốc, Trung Đồng Vân Trung | C11: Chợ địa phương | D11: 62000 | E11: =COUNTIF('Từng bài'!$P$2:$P$85,A11) | F11: T6 30/10 08:38 · góc 1; T3 03/11 07:52 · góc 7 | G11: 0 | H11: 0 | I11: =IF(G11=0,"-",H11/G11) | K11: Nhóm mới, chưa đăng lần nào: theo dõi bài đầu
A12: 738 | B12: Cộng đồng người Yên Thế - Bắc Giang | C12: Cộng đồng / hội | D12: 9900 | E12: =COUNTIF('Từng bài'!$P$2:$P$85,A12) | F12: T5 29/10 12:21 · góc 7; CN 01/11 16:17 · góc 3 | G12: 0 | H12: 0 | I12: =IF(G12=0,"-",H12/G12) | K12: Nhóm mới, chưa đăng lần nào: theo dõi bài đầu
A13: 558 | B13: FUYU HỒNG HẢI - KCN QUANG CHÂU - BẮC GIANG | C13: KCN / nhà trọ | D13: 35000 | E13: =COUNTIF('Từng bài'!$P$2:$P$85,A13) | F13: T5 29/10 21:47 · góc 5; T2 02/11 06:56 · góc 8 | G13: 0 | H13: 0 | I13: =IF(G13=0,"-",H13/G13) | K13: Nhóm mới, chưa đăng lần nào: theo dõi bài đầu
A14: 128 | B14: Hội Diều Sáo Tân Yên | C14: Cộng đồng / hội | D14: 52000 | E14: =COUNTIF('Từng bài'!$P$2:$P$85,A14) | F14: T7 31/10 17:45 · góc 8; T3 03/11 21:46 · góc 5 | G14: 1 | H14: 1 | I14: =IF(G14=0,"-",H14/G14) | J14: 2026-10-27 | K14: Tốt: phần lớn bài hiện ngay
A15: 794 | B15: Hội chăn nuôi gà Gà Đồi Yên Thế | C15: Cộng đồng / hội | D15: 12000 | E15: =COUNTIF('Từng bài'!$P$2:$P$85,A15) | F15: T6 30/10 16:07 · góc 9; T2 02/11 21:28 · góc 5 | G15: 0 | H15: 0 | I15: =IF(G15=0,"-",H15/G15) | K15: Nhóm mới, chưa đăng lần nào: theo dõi bài đầu
A16: 545 | B16: KCN QUANG CHÂU - VIỆT YÊN - BẮC GIANG | C16: KCN / nhà trọ | D16: 62000 | E16: =COUNTIF('Từng bài'!$P$2:$P$85,A16) | F16: T5 29/10 10:35 · góc 6; CN 01/11 12:33 · góc 4 | G16: 0 | H16: 0 | I16: =IF(G16=0,"-",H16/G16) | K16: Nhóm mới, chưa đăng lần nào: theo dõi bài đầu
A17: 540 | B17: KCN Đình Trám, Hoà Phú, Vân Trung, Quang Châu, Song Khê Bắc Giang | C17: KCN / nhà trọ | D17: 101000 | E17: =COUNTIF('Từng bài'!$P$2:$P$85,A17) | F17: T6 30/10 21:56 · góc 5; T3 03/11 12:42 · góc 10 | G17: 2 | H17: 2 | I17: =IF(G17=0,"-",H17/G17) | J17: 2026-10-24 | K17: Tốt: phần lớn bài hiện ngay
A18: 543 | B18: NHÀ TRỌ KCN ĐÌNH TRÁM, VÂN TRUNG, QUANG CHÂU | C18: KCN / nhà trọ | D18: 66000 | E18: =COUNTIF('Từng bài'!$P$2:$P$85,A18) | F18: T5 29/10 13:58 · góc 8; T2 02/11 13:16 · góc 4 | G18: 0 | H18: 0 | I18: =IF(G18=0,"-",H18/G18) | K18: Nhóm mới, chưa đăng lần nào: theo dõi bài đầu
A19: 784 | B19: Người Tân Yên | C19: Cộng đồng / hội | D19: 18000 | E19: =COUNTIF('Từng bài'!$P$2:$P$85,A19) | F19: T6 30/10 12:10 · góc 6; T2 02/11 17:54 · góc 3 | G19: 0 | H19: 0 | I19: =IF(G19=0,"-",H19/G19) | K19: Nhóm mới, chưa đăng lần nào: theo dõi bài đầu
A20: 539 | B20: Nhà Trọ KCN Đình Trám, Quang Châu, Vân Trung, Song Khê | C20: KCN / nhà trọ | D20: 121000 | E20: =COUNTIF('Từng bài'!$P$2:$P$85,A20) | F20: T5 29/10 08:26 · góc 2; T2 02/11 09:26 · góc 10 | G20: 0 | H20: 0 | I20: =IF(G20=0,"-",H20/G20) | K20: Nhóm mới, chưa đăng lần nào: theo dõi bài đầu
A21: 544 | B21: Nhà trọ quang châu | C21: KCN / nhà trọ | D21: 63000 | E21: =COUNTIF('Từng bài'!$P$2:$P$85,A21) | F21: T5 29/10 18:39 · góc 12; T2 02/11 19:10 · góc 5 | G21: 0 | H21: 0 | I21: =IF(G21=0,"-",H21/G21) | K21: Nhóm mới, chưa đăng lần nào: theo dõi bài đầu
A22: 49 | B22: Nhà Đất xã Yên Thế, Đồng Kỳ, Xuân Lương, Tam Tiến, Bố Hạ tỉnh Bắc Ninh | C22: Nhà đất / BĐS | D22: 1200 | E22: =COUNTIF('Từng bài'!$P$2:$P$85,A22) | F22: T4 28/10 18:39 · góc 12; CN 01/11 10:01 · góc 11 | G22: 4 | H22: 4 | I22: =IF(G22=0,"-",H22/G22) | J22: 2026-10-22 | K22: Tốt: phần lớn bài hiện ngay
A23: 547 | B23: Rao Vặt + Ăn Vặt Chợ Phước Yên - KCN Hòa Phú Có Ship | C23: KCN / nhà trọ | D23: 59000 | E23: =COUNTIF('Từng bài'!$P$2:$P$85,A23) | F23: T6 30/10 13:59 · góc 7; T3 03/11 14:53 · góc 12 | G23: 0 | H23: 0 | I23: =IF(G23=0,"-",H23/G23) | K23: Nhóm mới, chưa đăng lần nào: theo dõi bài đầu
A24: 255 | B24: Sơn Toa Yên Thế | C24: Cộng đồng / hội | D24: 16000 | E24: =COUNTIF('Từng bài'!$P$2:$P$85,A24) | F24: T7 31/10 07:25 · góc 11; T3 03/11 10:42 · góc 9 | G24: 1 | H24: 1 | I24: =IF(G24=0,"-",H24/G24) | J24: 2026-10-27 | K24: Tốt: phần lớn bài hiện ngay
A25: 783 | B25: Tân Yên - Bắc Giang | C25: Cộng đồng / hội | D25: 20000 | E25: =COUNTIF('Từng bài'!$P$2:$P$85,A25) | F25: T6 30/10 07:00 · góc 4; T2 02/11 10:58 · góc 11 | G25: 0 | H25: 0 | I25: =IF(G25=0,"-",H25/G25) | K25: Nhóm mới, chưa đăng lần nào: theo dõi bài đầu
A26: 100 | B26: XÃ XUÂN LƯƠNG - TỈNH BẮC NINH (Xuân Lương -Canh Nậu- Đồng Tiến ) | C26: Cộng đồng / hội | D26: 11000 | E26: =COUNTIF('Từng bài'!$P$2:$P$85,A26) | F26: T5 29/10 07:20 · góc 1; CN 01/11 11:09 · góc 12 | G26: 0 | H26: 0 | I26: =IF(G26=0,"-",H26/G26) | K26: Nhóm mới, chưa đăng lần nào: theo dõi bài đầu
A27: 789 | B27: Xã Phúc Hoà - Tỉnh Bắc Ninh ( Hợp Đức- Tân Yên-Bắc Giang) | C27: Cộng đồng / hội | D27: 6700 | E27: =COUNTIF('Từng bài'!$P$2:$P$85,A27) | F27: T6 30/10 17:41 · góc 10; T3 03/11 06:36 · góc 6 | G27: 0 | H27: 0 | I27: =IF(G27=0,"-",H27/G27) | K27: Nhóm mới, chưa đăng lần nào: theo dõi bài đầu
A28: 20 | B28: Xã Đồng Kỳ - Bắc Ninh ( Mới ): Thông Tin - Trao Đổi, Mua Bán | C28: Cộng đồng / hội | D28: 0 | E28: =COUNTIF('Từng bài'!$P$2:$P$85,A28) | F28: T4 28/10 20:32 · góc 5; CN 01/11 18:35 · góc 7 | G28: 4 | H28: 4 | I28: =IF(G28=0,"-",H28/G28) | J28: 2026-10-22 | K28: Tốt: phần lớn bài hiện ngay
A29: 785 | B29: Yên Thế - Bắc Giang | C29: Cộng đồng / hội | D29: 7900 | E29: =COUNTIF('Từng bài'!$P$2:$P$85,A29) | F29: T6 30/10 10:53 · góc 3; T2 02/11 12:34 · góc 12 | G29: 0 | H29: 0 | I29: =IF(G29=0,"-",H29/G29) | K29: Nhóm mới, chưa đăng lần nào: theo dõi bài đầu
A30: 48 | B30: Yên Thế Bắc Giang | C30: Cộng đồng / hội | D30: 7300 | E30: =COUNTIF('Từng bài'!$P$2:$P$85,A30) | F30: T5 29/10 17:10 · góc 11; CN 01/11 22:01 · góc 5 | G30: 3 | H30: 3 | I30: =IF(G30=0,"-",H30/G30) | J30: 2026-10-24 | K30: Tốt: phần lớn bài hiện ngay
A31: 46 | B31: Yên Thế Online | C31: Cộng đồng / hội | D31: 13000 | E31: =COUNTIF('Từng bài'!$P$2:$P$85,A31) | F31: T4 28/10 21:47 · góc 5; CN 01/11 06:46 · góc 9 | G31: 4 | H31: 4 | I31: =IF(G31=0,"-",H31/G31) | J31: 2026-10-25 | K31: Tốt: phần lớn bài hiện ngay
A32: 763 | B32: BẤT ĐỘNG SẢN BẮC GIANG | C32: Nhà đất / BĐS | D32: 235000 | E32: =COUNTIF('Từng bài'!$P$2:$P$85,A32) | F32: T5 29/10 10:15 · góc 0 | G32: 0 | H32: 0 | I32: =IF(G32=0,"-",H32/G32) | K32: Nhóm mới, chưa đăng lần nào: theo dõi bài đầu
A33: 130 | B33: Bất Động Sản Tân Yên Bắc Giang | C33: Nhà đất / BĐS | D33: 47000 | E33: =COUNTIF('Từng bài'!$P$2:$P$85,A33) | F33: T3 03/11 18:42 · góc 2 | G33: 5 | H33: 5 | I33: =IF(G33=0,"-",H33/G33) | J33: 2026-10-26 | K33: Tốt: phần lớn bài hiện ngay
A34: 552 | B34: CHỢ TRUNG ĐỒNG, Vân Cốc 1,2,3,4 Vân Trung Quang Châu | C34: Chợ địa phương | D34: 45000 | E34: =COUNTIF('Từng bài'!$P$2:$P$85,A34) | F34: T7 31/10 19:14 · góc 5 | G34: 0 | H34: 0 | I34: =IF(G34=0,"-",H34/G34) | K34: Nhóm mới, chưa đăng lần nào: theo dõi bài đầu
A35: 551 | B35: CHỢ VÂN CỐC 1,2,3,4 VÂN TRUNG _ TRUNG ĐỒNG _ BÀI XANH | C35: Chợ địa phương | D35: 52000 | E35: =COUNTIF('Từng bài'!$P$2:$P$85,A35) | F35: T7 31/10 13:16 · góc 3 | G35: 0 | H35: 0 | I35: =IF(G35=0,"-",H35/G35) | K35: Nhóm mới, chưa đăng lần nào: theo dõi bài đầu
A36: 311 | B36: Chợ Chùa Hang Linh Sơn Đồng Hỷ Thái Nguyên | C36: Chợ địa phương | D36: 59000 | E36: =COUNTIF('Từng bài'!$P$2:$P$85,A36) | F36: T4 28/10 08:26 · góc 2 | G36: 0 | H36: 0 | I36: =IF(G36=0,"-",H36/G36) | K36: Nhóm mới, chưa đăng lần nào: theo dõi bài đầu
A37: 114 | B37: Chợ Mọc Cao Thượng - Tân Yên - Bắc Giang | C37: Chợ địa phương | D37: 44000 | E37: =COUNTIF('Từng bài'!$P$2:$P$85,A37) | F37: CN 01/11 13:15 · góc 1 | G37: 3 | H37: 1 | I37: =IF(G37=0,"-",H37/G37) | J37: 2026-10-24 | K37: Một phần bài phải chờ duyệt
A38: 308 | B38: Chợ Nhà Đất Lạng Sơn - Nơi mua bán, thuê và cho thuê bất động sản Lạng Sơn | C38: Nhà đất / BĐS | D38: 170000 | E38: =COUNTIF('Từng bài'!$P$2:$P$85,A38) | F38: T4 28/10 15:52 · góc 10 | G38: 1 | H38: 1 | I38: =IF(G38=0,"-",H38/G38) | J38: 2026-10-23 | K38: Tốt: phần lớn bài hiện ngay
A39: 123 | B39: Chợ Tân Yên - Bắc Giang | C39: Chợ địa phương | D39: 30000 | E39: =COUNTIF('Từng bài'!$P$2:$P$85,A39) | F39: T7 31/10 14:42 · góc 6 | G39: 5 | H39: 5 | I39: =IF(G39=0,"-",H39/G39) | J39: 2026-10-26 | K39: Tốt: phần lớn bài hiện ngay
A40: 557 | B40: Chợ Vân Cốc 1,2,3,4. Kcn Vân Trung. My Điền. Nội Hoang Quang Châu | C40: KCN / nhà trọ | D40: 35000 | E40: =COUNTIF('Từng bài'!$P$2:$P$85,A40) | F40: CN 01/11 20:13 · góc 5 | G40: 0 | H40: 0 | I40: =IF(G40=0,"-",H40/G40) | K40: Nhóm mới, chưa đăng lần nào: theo dõi bài đầu
...

Sheet Theo loại bài
A1: Góc | B1: Loại bài (góc) | C1: Vì sao dùng góc này | D1: Số bài tuần này | E1: Đăng vào loại nhóm nào | F1: Ví dụ tiêu đề
A2: 0 | B2: Cho thuê văn phòng Sun City | C2: Mặt tiền Hùng Vương, 240–1.200 m², video định vị | D2: =COUNTIF('Từng bài'!$D$2:$D$85,A2) | E2: Nhà đất / BĐS 2 | F2: 🏢 MẶT BẰNG 1.200 M² TẦNG 2 SUN CITY: LÀM VĂN PHÒNG, TRUNG TÂM ĐÀO TẠO ĐỀU HỢP
A3: 1 | B3: Rủ anh em, họ hàng mua gần nhau | C3: Khách mua theo cụm làng/dòng họ, truyền miệng mạnh | D3: =COUNTIF('Từng bài'!$D$2:$D$85,A3) | E3: Nhà đất / BĐS 2, Cộng đồng / hội 2, Chợ địa phương 2, KCN / nhà trọ 1 | F3: 🏡 RỦ ANH EM XEM ĐẤT? CHỈ VỚI 500 TRIỆU ĐÃ SỞ HỮU LÔ ĐẤT
A4: 2 | B4: Hai vợ chồng cùng đi xem | C4: Vợ cùng quyết định; nhiều nữ đứng tên | D4: =COUNTIF('Từng bài'!$D$2:$D$85,A4) | E4: Chợ địa phương 2, KCN / nhà trọ 2, Cộng đồng / hội 2, Nhà đất / BĐS 1 | F4: 🏡 VỢ CHỒNG LÀM NHÀ? CHỈ VỚI 500 TRIỆU ĐÃ SỞ HỮU LÔ ĐẤT
A5: 3 | B5: Đất làm nhà cưới cho con | C5: Cha mẹ 45–65 tuổi mua cho con; cuối năm mùa cưới | D5: =COUNTIF('Từng bài'!$D$2:$D$85,A5) | E5: Cộng đồng / hội 4, Chợ địa phương 1 | F5: 🏡 ĐẤT CHO CON? CHỈ VỚI 500 TRIỆU ĐÃ SỞ HỮU LÔ ĐẤT
A6: 4 | B6: Tết về quê có đất riêng | C6: Người Yên Thế/Tân Yên làm ăn xa quê | D6: =COUNTIF('Từng bài'!$D$2:$D$85,A6) | E6: Cộng đồng / hội 2, KCN / nhà trọ 2, Nhà đất / BĐS 1 | F6: 🧧 MONG TẾT VỀ QUÊ: CHỈ VỚI 500 TRIỆU ĐÃ SỞ HỮU LÔ ĐẤT
A7: 5 | B7: Tối cho con ra quảng trường chơi | C7: Quảng trường sáng đèn, cầu trượt (đăng sau 19h) | D7: =COUNTIF('Từng bài'!$D$2:$D$85,A7) | E7: Cộng đồng / hội 6, KCN / nhà trọ 6, Nhà đất / BĐS 3, Chợ địa phương 2 | F7: 🌙 QUẢNG TRƯỜNG SÁNG ĐÈN: CHỈ VỚI 500 TRIỆU ĐÃ SỞ HỮU LÔ ĐẤT
A8: 6 | B8: Dạo một vòng bằng flycam | C8: Ảnh thật tạo tin; chú thích từng ảnh | D8: =COUNTIF('Từng bài'!$D$2:$D$85,A8) | E8: KCN / nhà trọ 2, Cộng đồng / hội 2, Nhà đất / BĐS 1, Chợ địa phương 1 | F8: 📍 XEM TỪ TRÊN CAO? CHỈ VỚI 500 TRIỆU ĐÃ SỞ HỮU LÔ ĐẤT
A9: 7 | B9: Hỏi nhanh – đáp nhanh | C9: Khách hay hỏi: sổ, giá, vay, ai dẫn đi xem | D9: =COUNTIF('Từng bài'!$D$2:$D$85,A9) | E9: Cộng đồng / hội 2, KCN / nhà trọ 2, Nhà đất / BĐS 1, Chợ địa phương 1 | F9: ✅ HỎI TRƯỚC KHI MUA? CHỈ VỚI 500 TRIỆU ĐÃ SỞ HỮU LÔ ĐẤT
A10: 8 | B10: Làm KCN, về quê có đất | C10: Gia đình trẻ làm KCN Quang Châu/Đình Trám | D10: =COUNTIF('Từng bài'!$D$2:$D$85,A10) | E10: KCN / nhà trọ 3, Nhà đất / BĐS 1, Cộng đồng / hội 1, Chợ địa phương 1 | F10: 🏡 ĐI CA KCN? CHỈ VỚI 500 TRIỆU ĐÃ SỞ HỮU LÔ ĐẤT
A11: 9 | B11: Khu dân cư mới giữa trung tâm xã | C11: Đường nhựa, đèn, quảng trường, sân thể thao | D11: =COUNTIF('Từng bài'!$D$2:$D$85,A11) | E11: Cộng đồng / hội 4, Chợ địa phương 2 | F11: 📍 KHU DÂN CƯ MỚI? CHỈ VỚI 500 TRIỆU ĐÃ SỞ HỮU LÔ ĐẤT
A12: 10 | B12: Nhìn từ trên cao / mặt đường | C12: Flycam dọc đường tỉnh, toàn khu | D12: =COUNTIF('Từng bài'!$D$2:$D$85,A12) | E12: KCN / nhà trọ 3, Nhà đất / BĐS 1, Cộng đồng / hội 1 | F12: 📍 CHỌN ĐẤT XÂY NHÀ? CHỈ VỚI 500 TRIỆU ĐÃ SỞ HỮU LÔ ĐẤT
A13: 11 | B13: Vẫn có khách giao dịch, CĐT dẫn đi xem | C13: Tạo lòng tin, mời hẹn ngày xem | D13: =COUNTIF('Từng bài'!$D$2:$D$85,A13) | E13: Cộng đồng / hội 3, Nhà đất / BĐS 2, Chợ địa phương 1 | F13: 🔥 HẸN NGÀY XEM ĐẤT? CHỈ VỚI 500 TRIỆU ĐÃ SỞ HỮU LÔ ĐẤT
A14: 12 | B14: Người các xã lân cận | C14: Gọi tên xã/vùng của nhóm | D14: =COUNTIF('Từng bài'!$D$2:$D$85,A14) | E14: KCN / nhà trọ 3, Cộng đồng / hội 2, Nhà đất / BĐS 1 | F14: 🏡 Ở QUANH YÊN THẾ? CHỈ VỚI 500 TRIỆU ĐÃ SỞ HỮU LÔ ĐẤT

Sheet Giải thích
A1: Cột | B1: Nghĩa
A2: Góc / Loại bài | B2: Câu chuyện chính của bài: 12 góc Golden Hill + 1 loại cho thuê Sun City (nguồn: workspace/research/2026-09-28-goc-sang-tao.md)
A3: Đối tượng | B3: Người đọc chính bài nhắm tới
A4: Mã khách báo | B4: Khách gọi/Zalo 0965.539.599 báo mã này → biết khách đến từ bài nào, nhóm nào
A5: Loại nhóm | B5: Xếp theo tên nhóm: Nhà đất/BĐS · Cộng đồng/hội · KCN/nhà trọ · Chợ địa phương
A6: Trạng thái | B6: Đã hiện = lên nhóm ngay · Chờ nhóm duyệt = quản trị viên chưa duyệt · Hẹn đăng = máy tự đăng đúng giờ · Hỏng = máy đăng không được
A7: Tỉ lệ hiện ngay | B7: Trong các bài đã đăng vào nhóm đó trước 28/10, bao nhiêu phần trăm hiện ngay không phải chờ duyệt
A8: Cập nhật | B8: Xuất lại từ cơ sở dữ liệu; không sửa tay trang 'Từng bài' vì các trang khác đếm từ đó
